Workbook

Sheet Sheet1
A1: Name | B1: Path | C1: Access | D1: Modality | E1: Body Part | F1: Format | G1: Shape | H1: Resolution | I1: Task | J1: Other Data (e.g., masks) | K1: Websites | L1: References | N1: # Images | O1: Format | P1: Location | Q1: File | R1: Downloaded | S1: Decompressed | T1: Agreement Required | U1: Agreement Submitted | V1: Approved | W1: Processed | X1: Link | Y1: Link2 | AA1: Notes | AG1: Path
A2: RP3D-DiagDS | B2: https://github.com/qiaoyu-zheng/RP3D-Diag | C2: Missing | D2: CT, MRI, US, X-Ray, NM | E2: Head&Neck, Abdomen&Pelvis,LowerLimb,UpperLimb,Chest,Spine,Breast | I2: Classification | J2: labeled with 5569 disorder labels and 931 ICD-10-CM disorder labels (coarse mapping); some cases include images from multiple modalities (~20%) | K2: https://qiaoyu-zheng.github.io/RP3D-Diag/ | N2: 5274618 | R2: FALSE | T2: TRUE | U2: TRUE | V2: FALSE | W2: FALSE | X2: https://huggingface.co/datasets/QiaoyuZheng/RP3D-DiagDS
A3: ULS23 | B3: /mnt/data-nas/medical_datasets/ULS23 | C3: Yes | D3: CT | E3: Whole Body | F3: .nii | H3: 256 × 256 × 128 | I3: Segmentation | J3: lesion segmentation, masks, 2D and 3D | K3: https://www.sciencedirect.com/science/article/pii/S1361841525000738?utm_source=chatgpt.com | N3: 4240609 | P3: NAS | Q3: NAS: ULS23 | R3: TRUE | S3: TRUE | X3: https://uls23.grand-challenge.org/uls23/
A4: SAM-Med2D-20M | B4: /mnt/data-nas/medical_datasets/SAM-Med2D-20M | C4: Yes | D4: CT, MRI, PET, X-Ray, Ultrasound, Endoscopy, Microscopy, Ophthalmic | E4: Head, Brain, Abdomen, Chest | F4: .png | H4: 256 x 256 pixels | I4: Segmentation | J4: Masks of corresponding images | K4: https://huggingface.co/datasets/OpenGVLab/SA-Med2D-20M | L4: https://arxiv.org/abs/2311.11969 | N4: 3769486 | P4: NAS | Q4: NAS: SAM-Med2D-20M | R4: TRUE | S4: FALSE | X4: https://huggingface.co/datasets/OpenGVLab/SA-Med2D-20M
A5: FastMRI | B5: /mnt/data-nas/medical_datasets/FastMRI | C5: Yes | D5: MRI | E5: Knee, Brain, Prostate, Breast | F5: .dcm | I5: Reconstruction | J5: Raw data from single and multi coils,fully-sampled ground-truth images | K5: https://fastmri.med.nyu.edu/ | L5: https://arxiv.org/pdf/1811.08839 | N5: 2453909 | P5: NAS | Q5: NAS: FastMRI | R5: TRUE | S5: FALSE | T5: TRUE | U5: TRUE | X5: https://fastmri.med.nyu.edu
A6: HCP | B6: /mnt/data-nas/medical_datasets/HCP | C6: Yes | D6: MRI (rfMRI,fMRI,dMRI,tfMRI) | E6: Brain | H6: 0.7 mm × 0.7 mm × 0.7 mm | I6: Classification | K6: https://www.humanconnectome.org/study/hcp-young-adult/document/hcp-young-adult-2025-release | N6: 1424290 | R6: FALSE | T6: TRUE | X6: https://www.humanconnectome.org/study/hcp-young-adult/data-releases | AA6: Download the Structural MRI package
A7: RadImageNet | B7: /mnt/data-nas/medical_datasets/radiology_ai | C7: Yes | D7: CT, MRI, US | E7: Abdomen | F7: .png | G7: 224x224x3 | H7: 224 x 224 pixels | I7: Classification | J7: Pathological labels | K7: https://www.radimagenet.com | L7: https://pubs.rsna.org/doi/full/10.1148/ryai.210315 | N7: 1078477 | P7: NAS | Q7: NAS: radiology_ai | R7: TRUE | S7: TRUE | T7: TRUE | U7: TRUE | V7: TRUE | W7: FALSE | X7: https://www.radimagenet.com | Y7: https://drive.google.com/file/d/1nQhybYZ7EBA886LaaR1vWm7BqKGEiHEf/view | AA7: NoDerivatives
A8: Quilt-1M | B8: /mnt/data-nas/medical_datasets/Quilt-1M | C8: Yes | D8: Microscopy | E8: Whole Body | F8: .jpg, .png | H8: Multiple (average 882 x 1468) | I8: CLIP (zero-shot linear probing and cross-modal retrieval) | J8: Medical text, ROI (region of interest) text, sub-pathology text labels | K8: https://quilt1m.github.io/ | L8: https://arxiv.org/abs/2306.11207 | N8: 643526 | P8: NAS | Q8: NAS: Quilt-1M | R8: TRUE | S8: TRUE | T8: TRUE | U8: TRUE | V8: TRUE | W8: TRUE | X8: https://github.com/wisdomikezogwo/quilt1m?tab=readme-ov-file | Y8: https://zenodo.org/records/8239942
A9: ISIC-2024 | B9: /mnt/data-nas/medical_datasets/ISIC_2024_Training_Input | C9: Yes | D9: Dermoscopy | E9: Skin | F9: .jpg | G9: (155, 155, 3) | H9: 15 mm × 15 mm (Field of View) | I9: Classification | J9: Images come from different places, different resolution but same FoV. 2D JPEGS | K9: https://www.kaggle.com/competitions/isic-2024-challenge | N9: 401059 | P9: NAS | Q9: NAS: ISIC_2024_Training_Input | R9: TRUE | S9: TRUE | W9: TRUE | X9: https://challenge2024.isic-archive.com
A10: VinDr-Multiphase | B10: /mnt/data-nas/medical_datasets/VinDr-Multiphase | C10: Yes | D10: CT | E10: Abdomen | F10: .dcm , .dicom | G10: 512x512 | H10: 512 x 512 pixels | I10: Classification | J10: Phase labels | K10: https://vindr.ai/datasets/abdomen-phases | L10: https://pubmed.ncbi.nlm.nih.gov/35428990/ | N10: 392559 | P10: NAS | Q10: NAS: VinDr-Multiphase | R10: TRUE | T10: TRUE | U10: TRUE | V10: TRUE | W10: TRUE | X10: https://vindr.ai/datasets/abdomen-phases
A11: MIMIC-CXR | B11: /mnt/data-nas/biovfm/mimic-cxr-jpg-2.1.0 | C11: Yes | D11: X-Ray | E11: Chest | F11: .jpg | G11: HXW (2544X3056) | H11: 512x512 to 4096x4096 pixels | I11: Self-supervised/CLIP | J11: Radiology reports, study and patient identifiers, examination name, multiple images per patient | K11: https://physionet.org/content/mimic-cxr/2.1.0/ | L11: https://www.nature.com/articles/s41597-019-0322-0 | N11: 377100 | P11: NAS | Q11: NAS: mimic-cxr-jpg-2.1.0 | R11: TRUE | S11: TRUE | W11: TRUE | X11: https://github.com/MIT-LCP/mimic-cxr
A12: PatchCamelyon | B12: /mnt/data-nas/medical_datasets/PatchCamelyon | C12: Yes | D12: Microscopy | E12: Microscopy | F12: .png | H12: 96x96 | I12: Classification | J12: Histopathologic scans of lymph node sections | K12: https://github.com/basveeling/pcam | N12: 262144 | P12: NAS | Q12: NAS: PatchCamelyon | R12: TRUE | S12: TRUE | X12: https://patchcamelyon.grand-challenge.org
A13: CheXpert | B13: /mnt/data-nas/medical_datasets/chexpert | C13: Yes | D13: X-Ray | E13: Chest | F13: .png | H13: 2000 x 2000 to 3000 x 3000 pixels | I13: Classification | J13: Pathological labels | K13: https://stanfordmlgroup.github.io/competitions/chexpert/ | L13: https://arxiv.org/abs/1901.07031 | N13: 223414 | P13: NAS | Q13: ? | R13: TRUE | S13: TRUE | W13: FALSE | X13: https://stanfordmlgroup.github.io/competitions/chexpert/ | AA13: location?
A14: PadChest | B14: /mnt/data-nas/medical_datasets/PadChest | C14: Yes | D14: X-Ray | E14: Chest | F14: .png | H14: Multiple (high res. ~1500-2800) | I14: Classification | J14: Multiple images per patient, radiography report in spanish, metadata about patient and image (birth, sex...) | K14: https://bimcv.cipf.es/bimcv-projects/padchest/ | L14: https://www.sciencedirect.com/science/article/pii/S1361841520301614?via%3Dihub | N14: 160828 | P14: NAS | Q14: NAS: PadChest | R14: TRUE | T14: TRUE | U14: TRUE | X14: https://bimcv.cipf.es/bimcv-projects/padchest/ | Y14: https://b2drop.bsc.es/index.php/s/BIMCV-PadChest-FULL
A15: EyePACS | B15: /mnt/data-nas/medical_datasets/EyePACS | C15: Yes | D15: Ophthalmic | E15: Fundus | F15: .jpeg | G15: HXWX3 | H15: 433 x 289 pixels to 5184 x 3456 pixels | I15: Classification | J15: diabetic retinopathy fundus images, graded from 0 to 4 | K15: https://www.kaggle.com/c/diabetic-retinopathy-detection/ | N15: 101400 | P15: NAS | Q15: NAS: EyePACS | R15: TRUE | S15: TRUE | T15: TRUE | U15: TRUE | W15: TRUE | X15: https://www.kaggle.com/c/diabetic-retinopathy-detection/
A16: NCT-CRC-HE-100K | B16: /mnt/data-nas/medical_datasets/NCT-CRC-HE-100K | C16: Yes | D16: Microscopy | E16: Abdomen | F16: .tif | G16: 224x224x3 | H16: 224 x 224 pixels | I16: Classification | J16: Pathological labels | K16: https://zenodo.org/records/1214456 | N16: 100000 | P16: NAS | Q16: NAS: NCT-CRC-HE-100K | R16: TRUE | S16: TRUE | W16: TRUE | X16: https://zenodo.org/records/1214456
A17: Endo-FM | B17: /mnt/data-nas/medical_datasets/Endo-FM | C17: Yes | D17: Endoscopy | E17: Gastrointestinal | F17: .mp4 | I17: Self-supervised (classification, segmentation, detection) | K17: https://arxiv.org/abs/2306.16741 | N17: 93015 | P17: NAS | Q17: NAS: Endo-FM.tar | R17: TRUE | S17: FALSE | W17: FALSE | X17: https://github.com/openmedlab/Endo-FM#pre-training-data-6-public--1-private
A18: ChestXray-14 | B18: /mnt/data-nas/medical_datasets/ChestXray-14 | C18: Yes | D18: X-Ray | E18: Chest | F18: .png | G18: 1024x1024 | H18: 1024 x 1024 pixels | I18: Classification | J18: 14 common thoracic pathologies | K18: https://bio-protocol.org/exchange/minidetail?id=17520318&type=30&utm_source=chatgpt.com | N18: 86524 | P18: NAS | Q18: NAS: ChestXray-14 | R18: TRUE | S18: TRUE | W18: TRUE | X18: https://www.kaggle.com/datasets/nih-chest-xrays/data
A19: Kvasir-Capsule | B19: /mnt/data-nas/medical_datasets/Kvasir-Capsule | C19: Yes | D19: Endoscopy | E19: Abdomen | F19: .jpg | G19: HXWX3 (336x336x3) | H19: 256 x 256 to 512 x 512 pixels | I19: Classification | J19: Pathological labels | K19: https://datasets.simula.no/kvasir-capsule/ | L19: https://www.nature.com/articles/s41597-021-00920-z | N19: 79473 | P19: NAS | Q19: NAS: Kvasir-Capsule | R19: TRUE | S19: TRUE | W19: TRUE | X19: https://datasets.simula.no/kvasir-capsule/
A20: ISIC-Archive | B20: /mnt/data-nas/medical_datasets/ISIC-Archive | C20: Yes | D20: Dermoscopy | E20: Skin | F20: .jpg,.png | G20: HXWX3, HXW | K20: https://api.isic-archive.com/images/ | N20: 58551 | P20: NAS | Q20: NAS: ISIC-Archive | R20: TRUE | S20: TRUE | W20: TRUE | X20: https://api.isic-archive.com/images/
A21: UW-Madison GI | B21: /mnt/data-nas/medical_datasets/UW-Madison-GI | C21: Yes | D21: MRI | E21: Gastrointestinal tract (Stomach, Abdomen) | F21: .png | H21: 266 x 266 pixels typically, but multiple | I21: Segmentation | J21: The filenames of the images in this dataset contain four numbers (e.g., 276_276_1.63_1.63.png), representing the width/height of the slice in pixels (as integers) and the pixel spacing in width/height (as floating-point numbers) in millimeters. The first two numbers define the resolution of the slice, while the last two indicate the physical size of each pixel. | K21: https://www.kaggle.com/competitions/uw-madison-gi-tract-image-segmentation | N21: 38496 | P21: NAS | Q21: NAS: UW-Madison-GI | R21: TRUE | S21: TRUE | T21: TRUE | U21: TRUE | X21: https://www.kaggle.com/competitions/uw-madison-gi-tract-image-segmentation/overview
A22: TDSC-ABUS | B22: /mnt/data-nas/medical_datasets/TDSC-ABUS | C22: Yes | D22: US | E22: Chest | F22: .nrrd | G22: 3d (865, 608, 330) | H22: 843 x 546 x 270 to 865 x 682 x 354 pixels | I22: Segmentation, Classification | J22: Tumor boundaries, benign / malignant label | K22: https://tdsc-abus2023.grand-challenge.org/TDSC-ABUS2023/, https://github.com/mralinp/tdsc-abus2023-pytorch/tree/main | L22: https://arxiv.org/abs/2501.15588 | N22: 34210 | P22: NAS | Q22: NAS: TDSC-ABUS | R22: TRUE | S22: TRUE | T22: TRUE | U22: TRUE | V22: FALSE | W22: FALSE | X22: https://tdsc-abus2023.grand-challenge.org/Dataset/ | AA22: (.nrrd)
A23: EchoNet-Dynamic | B23: /mnt/data-nas/medical_datasets/EchoNet-Dynamic | C23: Yes | D23: US | E23: Chest | F23: .mp4 | H23: 112 x 112 videos | I23: Segmentation, regression | J23: Video metadata (fps...), medical metadata (EF, ESV,EDV - heart related), tracing for left ventricle | K23: https://echonet.github.io/dynamic/ | L23: https://www.nature.com/articles/s41586-020-2145-8 | N23: 25608 | P23: NAS | Q23: NAS: EchoNet-Dynamic | R23: TRUE | S23: TRUE | T23: TRUE | U23: TRUE | W23: FALSE | X23: https://echonet.github.io/dynamic/ | AA23: NoDerivatives
A24: LC25000 | B24: /mnt/data-nas/medical_datasets/lung_colon_image_set | C24: Yes | D24: Microscopy | E24: Lung and Colon | F24: .jpeg | G24: 768x768x3 | H24: 768 x 768 pixels | I24: Classification | J24: This dataset is divided into 5 categories: colon adenocarcinoma, benign colon tissue, lung adenocarcinoma, lung squamous cell carcinoma, and benign lung tissue, with 5,000 images for each category. | K24: https://github.com/tampapath/lung_colon_image_set | N24: 25000 | P24: NAS | Q24: NAS: lung_colon_image_set | R24: TRUE | S24: TRUE | W24: FALSE | X24: https://github.com/tampapath/lung_colon_image_set | Y24: https://www.kaggle.com/datasets/javaidahmadwani/lc25000
A25: fitzpatrick17k | B25: /mnt/data-nas/biovfm/data/finalfitz17k | C25: Yes | D25: Dermoscopy | E25: Skin | F25: .jpg | G25: HXWX3 (1367,1734,3) | H25: 300 x 300 to 400 x 400 pixels | I25: Classification | J25: Skin conditions | K25: https://github.com/mattgroh/fitzpatrick17k/tree/main | L25: https://arxiv.org/abs/2104.09957 | N25: 16577 | P25: NAS | Q25: NAS: data | R25: TRUE | S25: TRUE | T25: TRUE | U25: TRUE | V25: TRUE | W25: TRUE | X25: https://github.com/mattgroh/fitzpatrick17k/tree/main | Y25: https://drive.google.com/file/d/1B_dHew_vLq3h8QH6ufzA1Eh9N7guB8uj/view
A26: VinDr-Mammo | B26: /mnt/data-nas/medical_datasets/VinDr-Mammo | C26: Yes | D26: X-Ray | E26: Breast | F26: (no location) | I26: Classification, Object detection | J26: 4 views per image, bounding box annotations, BI-RADS (findings label) and breast density | K26: https://vindr.ai/datasets/mammo | L26: https://www.medrxiv.org/content/10.1101/2022.03.07.22272009v1 | N26: 16000 | P26: NAS | Q26: ? | R26: TRUE | S26: FALSE | T26: TRUE | U26: TRUE | W26: FALSE | X26: https://vindr.ai/datasets/mammo | Y26: https://www.physionet.org/content/vindr-mammo/1.0.0/
A27: VinDr-CXR | B27: /mnt/data-nas/medical_datasets/VinDr-CXR | C27: Yes | D27: X-Ray | E27: Chest | F27: .dcm , .dicom | H27: 2788x2446 pixels median | I27: Classification | K27: https://vindr.ai/cxr | N27: 15000 | R27: FALSE | T27: TRUE | U27: TRUE | V27: FALSE | W27: FALSE | X27: https://vindr.ai/cxr | Y27: https://www.kaggle.com/c/vinbigdata-chest-xray-abnormalities-detection/data
A28: AOD | B28: /mnt/data-nas/medical_datasets/AOD | C28: Yes | D28: Ophthalmic | E28: Fundus | F28: .jpg | G28: H x W x 3 | H28: 1000 x 1000 to 3000 x 3000 pixels | I28: Classification | J28: Pathological labels | K28: https://www.kaggle.com/datasets/nurmukhammed7/augemnted-ocular-diseases | N28: 14813 | P28: NAS | Q28: NAS: AOD | R28: TRUE | S28: TRUE | W28: TRUE | X28: https://www.kaggle.com/datasets/nurmukhammed7/augemnted-ocular-diseases
A29: DDR | B29: /mnt/data-nas/medical_datasets/DDR | C29: Yes | D29: Ophthalmic | E29: Fundus | F29: .jpg | H29: Multiple | I29: Classification, Segmentation, Object detection | J29: Image DR (Diabetic Retinopathy) 6-level grading, masks for 4 lesions, bounding box following masks | K29: https://github.com/nkicsl/DDR-dataset | L29: http://www.sciencedirect.com/science/article/pii/S0020025519305377 | N29: 13671 | P29: NAS | Q29: NAS: DDR | R29: TRUE | S29: TRUE | X29: https://github.com/nkicsl/DDR-dataset
A30: VinDr-BodyPartXR | B30: /mnt/data-nas/medical_datasets/VinDr-BodyPartXR | C30: Yes | D30: X-Ray | E30: Full Body | F30: (permission denied) | H30: Multiple - no mentions on portals | I30: Classification | J30: Multiple body part X-ray classification | K30: https://vindr.ai/datasets/bodypartxr | N30: 11258 | P30: NAS | Q30: NAS: VinDr-BodyPartXR | R30: TRUE | T30: TRUE | U30: TRUE | V30: FALSE | W30: FALSE | X30: https://vindr.ai/datasets/bodypartxr
A31: VinDr-SpineXr | B31: /mnt/data-nas/medical_datasets/VinDr-SpineXR | C31: Yes | D31: X-Ray | E31: Head | F31: .dcm | H31: 2500 x 1600 pixels, various | I31: Classification | J31: Pathological labels | K31: https://vindr.ai/spinexr | L31: https://arxiv.org/abs/2106.12930 | N31: 8389 | P31: NAS | Q31: NAS: Vindr-SpineXR | R31: TRUE | S31: FALSE | T31: TRUE | U31: TRUE | X31: https://vindr.ai/spinexr | Y31: https://www.physionet.org/content/vindr-spinexr/1.0.0/
A32: Object-CXR | B32: /mnt/data-nas/medical_datasets/Object-CXR | C32: Yes | D32: X-Ray | E32: Chest | F32: .jpg | G32: HXW (3065, 2552) | I32: Object detection, Classification | J32: Bounding shape (rectangle, ellipse, polygon) for foreign objects | K32: https://web.archive.org/web/20201127235812/https://jfhealthcare.github.io/object-CXR/ | N32: 8000 | P32: NAS | Q32: NAS: Object-CXR | R32: TRUE | S32: TRUE | W32: FALSE | X32: https://web.archive.org/web/20201127235812/https://jfhealthcare.github.io/object-CXR/ | Y32: https://www.kaggle.com/datasets/raddar/foreign-objects-in-chest-xrays
A33: VinDr-PCXR | B33: /mnt/data-nas/medical_datasets/VinDr-PCXR | C33: Yes | D33: X-Ray | E33: Chest | F33: .dcm | H33: Multiple - no mentions on portals | I33: Classification | J33: pediatric CXR dataset | K33: https://vindr.ai/datasets/pediatric-chest-x-ray | N33: 7728 | P33: NAS | Q33: NAS: Vindr-PCXR | R33: TRUE | S33: FALSE | T33: TRUE | U33: TRUE | X33: https://vindr.ai/datasets/pediatric-chest-x-ray | Y33: https://physionet.org/content/vindr-pcxr/1.0.0/
A34: OpenI | B34: /mnt/data-nas/medical_datasets/OpenI | C34: Yes | D34: X-Ray | E34: Chest | F34: .png | G34: HXWX3 (624, 512, 3) | H34: 512 x 512 pixels, various | I34: N/A | K34: https://openi.nlm.nih.gov | L34: https://pmc.ncbi.nlm.nih.gov/articles/PMC5009925/ | N34: 7470 | P34: NAS | Q34: NAS: OpenI | R34: TRUE | S34: TRUE | W34: FALSE | X34: https://pmc.ncbi.nlm.nih.gov/articles/PMC5009925/ | Y34: https://openi.nlm.nih.gov/faq?download=true
A35: Messidor-2 | B35: /mnt/data-nas/medical_datasets/Messidor-2 | C35: Yes | D35: Ophthalmic | E35: Fundus | F35: .tif | G35: HXWX3 (1536,2304,3) | H35: 1440x960, 2240x1488,2304x1536 | I35: Retrieval, Quantization | J35: Retinopathy grade (lesion) and risk of macular edema label | K35: https://www.adcis.net/en/third-party/messidor/ | N35: 1744 | P35: NAS | Q35: NAS: Messidor-2 | R35: TRUE | S35: TRUE | T35: TRUE | U35: TRUE | W35: FALSE | X35: https://www.adcis.net/en/third-party/messidor/
A36: XCAD | B36: /mnt/data-nas/medical_datasets/XCAD | C36: Yes | D36: X-Ray | E36: Heart | F36: ,png | G36: 512x512 | H36: 512x512 pixels | I36: Segmentation | J36: The training set contains 1621 mask frames and 1621 coronary angiograms. | K36: https://github.com/AISIGSJTU/SSVS | N36: 1705 | P36: NAS | Q36: NAS: XCAD | R36: TRUE | S36: TRUE | W36: FALSE | X36: https://github.com/AISIGSJTU/SSVS
A37: ROSSA | B37: /mnt/data-nas/medical_datasets/ROSSA | C37: Yes | D37: Ophthalmic | E37: Fundus | F37: .png | G37: 320x320 | H37: 320 x 320 pixels | I37: Segmentation | J37: Vessel masks | K37: https://github.com/nhjydywd/OCTA-FRNet | L37: https://arxiv.org/abs/2309.09483 | N37: 818 | P37: NAS | Q37: NAS: ROSSA | R37: TRUE | S37: TRUE | W37: TRUE | X37: https://github.com/nhjydywd/OCTA-FRNet | Y37: https://github.com/nhjydywd/OCTA-FRNet/tree/main/dataset
A38: SARAS-ESAD | B38: /mnt/data-nas/medical_datasets/SARAS-ESAD | C38: Yes | D38: Endoscopy | E38: Prostate | F38: .jpg | G38: 1080x1920x3 | I38: Action detection | J38: Bounding box for action instances | K38: https://saras-esad.grand-challenge.org/Dataset/ | N38: 670 | P38: NAS | Q38: NAS: SARAS-ESAD | R38: TRUE | S38: TRUE | W38: FALSE | X38: https://saras-esad.grand-challenge.org/Dataset/
A39: ShenzhenCXR | B39: /mnt/data-nas/medical_datasets/ShenzhenCXR | C39: Yes | D39: X-Ray | E39: Chest | F39: .png | G39: HXWX3 | H39: 3000x3000 pixel median | I39: Classification | J39: The image file names follow the format CHNCXR_#####0/1.png, where '0' represents normal and '1' represents abnormal. | K39: https://github.com/openmedlab/Awesome-Medical-Dataset/blob/main/resources/Shenzhen_chest_X-ray.md | N39: 662 | P39: NAS | Q39: NAS: ShenzhenCXR | R39: TRUE | S39: TRUE | W39: FALSE | X39: https://openi.nlm.nih.gov/faq#faq-tb-coll | Y39: https://www.kaggle.com/datasets/raddar/tuberculosis-chest-xrays-shenzhen
A40: FIVES | B40: /mnt/data-nas/medical_datasets/FIVES | C40: Yes | D40: Ophthalmic | E40: Fundus | F40: .png | G40: 2048X2048X3 | H40: 2048 x 2048 pixels | I40: Segmentation | J40: Vessel masks | K40: https://figshare.com/articles/figure/FIVES_A_Fundus_Image_Dataset_for_AI-based_Vessel_Segmentation/19688169?file=34969398 | L40: https://www.nature.com/articles/s41597-022-01564-3 | N40: 598 | P40: NAS | Q40: NAS: FIVES | R40: TRUE | S40: TRUE | W40: FALSE | X40: https://figshare.com/articles/figure/FIVES_A_Fundus_Image_Dataset_for_AI-based_Vessel_Segmentation/19688169?file=34969398
...

Sheet New Datasets
A1: FileName | B1: Name | E1: Modality | H1: Link
A2: OpticNerveSeg_Public_Dataset_for_Cranial_Nerve_II_Segmentation_from_Multimodal_M_21457212 | B2: OpticNerveSeg: Public Dataset for Cranial Nerve II Segmentation from Multimodal MRI | E2: MRI | H2: https://zenodo.org/records/21457212
A3: Anonymised_Pelvic_MRI_Dataset_for_Endometriosis_Research_A_Nigerian_Pilot_Collec_21445496 | B3: Anonymised Pelvic MRI Dataset for Endometriosis Research: A Nigerian Pilot Collection | E3: MRI | H3: https://zenodo.org/records/21445496
A4: CBCT-IQ_A_Publicly_Available_Annotated_Cone-Beam_CT_Dataset_for_Image_Quality_As_20124496 | B4: CBCT-IQ: A Publicly Available Annotated Cone-Beam CT Dataset for Image Quality Assessment and Benchmarking | E4: CBCT | H4: https://zenodo.org/records/20124496
A5: Naija-CXR_dataset-JPG-A_Nigerian_Chest_X-ray_Dataset_for_Equitable_AI_and_Vision_21781842 | B5: Naija-CXR dataset-JPG-A Nigerian Chest X-ray Dataset for Equitable AI and Vision-Language Research | E5: X-ray | H5: https://zenodo.org/records/21781842
A6: Primary_Breast_Burkitt_Lymphoma_Multimodal_Imaging_Dataset_Immunohistochemistry__21470632 | B6: Primary Breast Burkitt Lymphoma Multimodal Imaging Dataset: Immunohistochemistry, Cytology, and Ultrasound Images from Uganda (Version 1.2) | E6: Ultrasound | H6: https://zenodo.org/records/21470632
A7: ToxoPath-1_A_Multimodal_Pathology_Dataset_of_Concurrent_Cerebral_and_Cardiac_Tox_21497156 | B7: ToxoPath-1: A Multimodal Pathology Dataset of Concurrent Cerebral and Cardiac Toxoplasmosis in an HIV-Positive Patient | E7: Pathology | H7: https://zenodo.org/records/21497156
A8: Histology_Tissue_Fold_Dataset_with_Pixel-Level_Annotations_for_Artificial_Intell_21493260 | B8: Histology Tissue Fold Dataset with Pixel-Level Annotations for Artificial Intelligence-Based Detection and Segmentation of Tissue Fold Artifacts in H&E-Stained Teaching Slides | E8: H&E | H8: https://zenodo.org/records/21493260
A9: Skin_Lesions_Dataset_for_2-Class_Object_Segmentation_(YOLO_annotation)_21416759 | B9: Skin Lesions Dataset for 2-Class Object Segmentation (YOLO annotation) | E9: Dermoscopy | H9: https://zenodo.org/records/21416759
A10: GIM-ENDO | B10: GIM-ENDO | E10: Endoscopy | H10: https://zenodo.org/records/20707267
A11: MSila | B11: M'Sila retinal fundus dataset | E11: Fundus | H11: https://zenodo.org/records/19169587
A12: FLUID | B12: FLUID | E12: Fundus | H12: https://zenodo.org/records/19241555
... A14: PTIC | B14: PathoTiroid Dataset Indonesian Collection (PTIC) | E14: Histopathology | H14: https://zenodo.org/records/18827019

Sheet Potential Evaluation Datasets
A1: LC25000 | C1: https://www.kaggle.com/datasets/javaidahmadwani/lc25000
A2: RSNA pneumonia dataset | C2: https://www.kaggle.com/competitions/rsna-pneumonia-detection-challenge
A3: ODIR-5k | C3: https://www.kaggle.com/datasets/tanjemahamed/odir5k-classification
A4: Retinal OCT Image Classification - C8 | C4: https://www.kaggle.com/datasets/obulisainaren/retinal-oct-c8

Sheet Sheet7
A1: Name | B1: Path | C1: Modality | D1: Count | E1: Moved | F1: Moved Location
A2: ULS23 | B2: /mnt/data-nas/medical_datasets/ULS23 | C2: CT | D2: 480056
A3: HCP | B3: /mnt/data-nas/medical_datasets/HCP | C3: MRI | D3: 39191 | E3: TRUE | F3: Delta
A4: RadImageNet | B4: /mnt/data-nas/medical_datasets/radiology_ai/CT/dontmove | C4: CT | D4: 292353
A5: RadImageNet | B5: /mnt/data-nas/medical_datasets/radiology_ai/MR/dontmove | C5: MRI | D5: 672675
A6: RadImageNet | B6: /mnt/data-nas/medical_datasets/radiology_ai/US/dontmove | C6: Ultrasound | D6: 389885
A7: Quilt-1M | B7: /mnt/data-nas/medical_datasets/Quilt-1M | C7: Microscopy | D7: 653136
A8: ISIC-2024 | B8: /mnt/data-nas/medical_datasets/ISIC_2024_Training_Input | C8: Dermoscopy | D8: 401059
A9: VinDr-Multiphase | B9: /mnt/data-nas/medical_datasets/VinDr-Multiphase | C9: CT | D9: 392560 | E9: FALSE | F9: Delta
A10: MIMIC-CXR | B10: /mnt/data-nas/biovfm/mimic-cxr-jpg-2.1.0 | C10: X-Ray | D10: 377110
A11: PatchCamelyon | B11: /mnt/data-nas/medical_datasets/PatchCamelyon | C11: Microscopy | D11: 327680
A12: CheXpert | B12: /mnt/data-nas/medical_datasets/chexpert | C12: X-Ray | D12: 223414
A13: PadChest | B13: /mnt/data-nas/medical_datasets/PadChest | C13: X-Ray | D13: 156525 | E13: FALSE | F13: Delta
A14: EyePACS | B14: /mnt/data-nas/medical_datasets/EyePACS | C14: Fundus | D14: 88712
A15: NCT-CRC-HE-100K | B15: /mnt/data-nas/medical_datasets/NCT-CRC-HE-100K | C15: Microscopy | D15: 100000
A16: Endo-FM | B16: /mnt/data-nas/medical_datasets/Endo-FM | C16: Endoscopy | D16: 1831457
A17: ChestXray-14 | B17: /mnt/data-nas/medical_datasets/ChestXray-14 | C17: X-Ray | D17: 112120
A18: Kvasir-Capsule | B18: /mnt/data-nas/medical_datasets/Kvasir-Capsule | C18: Endoscopy | D18: 47238
A19: ISIC-Archive | B19: /mnt/data-nas/medical_datasets/ISIC-Archive | C19: Dermoscopy | D19: 537969
A20: TDSC-ABUS | B20: /mnt/data-nas/medical_datasets/TDSC-ABUS | C20: Ultrasound | D20: 184741
A21: EchoNet-Dynamic | B21: /mnt/data-nas/medical_datasets/EchoNet-Dynamic | C21: Ultrasound | D21: 882309
A22: LC25000 | B22: /mnt/data-nas/medical_datasets/lung_colon_image_set | C22: Microscopy | D22: 25000
A23: fitzpatrick17k | B23: /mnt/data-nas/biovfm/data/finalfitz17k | C23: Dermoscopy | D23: 16577
A24: VinDr-CXR | B24: /mnt/data-nas/medical_datasets/VinDr-CXR | C24: X-Ray | D24: 18000
A25: AOD | B25: /mnt/data-nas/medical_datasets/AOD | C25: Fundus | D25: 14813
... A57: Covid-Xray | B57: /mnt/data-nas/medical_datasets/covid-chestxray-dataset/dontmove | C57: X-Ray | D57: 821
A58: Lung-PET | B58: /mnt/data-nas/medical_datasets/TCIA-DICOM/Lung-PET-CT-Dx | C58: CT | D58: 251135 | E58: TRUE | F58: Delta
A59: Radiomics | B59: /mnt/data-nas/medical_datasets/TCIA-DICOM/NSCLC-Radiomics | C59: CT | D59: 51230 | E59: TRUE | F59: Delta
A60: Yale | B60: /mnt/data-nas/medical_datasets/Yale | C60: MRI | D60: 335822
A61: ISPY1 | B61: /mnt/data-nas/vibalcam/datasets/ispy1 | C61: MRI | D61: 281937
A62: CSEC | B62: /mnt/data-nas/medical_datasets/TCGA-CESC | C62: MRI | D62: 18985
A63: VSSEG | B63: /mnt/data-nas/medical_datasets/VSSEG | C63: MRI | D63: 47130
A64: ISPY1Trial | B64: /mnt/data-nas/vibalcam/datasets/ispy1_trial | C64: MRI | D64: 385093
A65: DFCI | B65: /mnt/data-nas/medical_datasets/DFCI | C65: MRI | D65: 93892
A66: RSNA_BrainTumorRC | B66: /mnt/data-nas/medical_datasets/RSNA_BrainTumorRC | C66: MRI | D66: 290923
A67: HVSPCD | B67: /mnt/data-nas/medical_datasets/HVSPCD | C67: MRI | D67: 476353
A68: CSMLP | B68: /mnt/data-nas/medical_datasets/CSMLP | C68: MRI | D68: 90175
A69: COVID-CT-MD | B69: /mnt/data-nas/medical_datasets/COVID-CT-MD | C69: CT | D69: 902
A70: LIDC-IDRI | B70: /mnt/data-nas/vibalcam/datasets/LIDC-IDRI | C70: CT | D70: 244527
A71: QIN-LungCT-Seg | B71: /mnt/data-nas/vibalcam/datasets/QIN-LungCT-Seg | C71: CT | D71: 6814
...

Sheet Stats (Modality)
A1: Modality | B1: # Datasets | C1: # Images
A2: CT | B2: 5 | C2: =int(Sheet1!N2/4+Sheet1!N3+Sheet1!N4/8+Sheet1!N7/3+Sheet1!N10) -> 6782500
A3: MRI | B3: 6 | C3: =int(Sheet1!N2/4+Sheet1!N4/8+Sheet1!N5+Sheet1!N6+Sheet1!N7/3+Sheet1!N21) -> 6066027
A4: X-Ray | B4: 19 | C4: =int(Sheet1!N2/4+Sheet1!N4/8+Sheet1!N11+SUM(Sheet1!N13:N14)+Sheet1!N18+SUM(Sheet1!N26:N27)+SUM(Sheet1!N30:N34)+Sheet1!N36+Sheet1!N39+Sheet1!N42+Sheet1!N46+Sheet1!N48+Sheet1!N53) -> 2714752
A5: US | B5: 5 | C5: =int(Sheet1!N2/4+Sheet1!N7/3+Sheet1!N22+Sheet1!N23+Sheet1!N47) -> 1738127
A6: Microscopy | B6: 5 | C6: =int(Sheet1!N4/8+Sheet1!N8+Sheet1!N12+Sheet1!N16+Sheet1!N24) -> 1501855
A7: Endoscopy | B7: 4 | C7: =int(Sheet1!N4/8+Sheet1!N17+Sheet1!N19+Sheet1!N38) -> 644343
A8: Ophthalmic | B8: 24 | C8: =int(SUM(Sheet1!N4/8,Sheet1!N15,Sheet1!N28:N29,Sheet1!N35,Sheet1!N37,Sheet1!N40:N41,Sheet1!N43:N45,Sheet1!N49:N52,Sheet1!N54:N62)) -> 606538
A9: Dermoscopy | B9: 3 | C9: =int(Sheet1!N9+Sheet1!N20+Sheet1!N25) -> 476187
A10: PET | B10: 1 | C10: =int(Sheet1!N4/8) -> 471185

Sheet OmniMed-30M
A1: Name | B1: Path | C1: Modality | D1: Count | E1: is_3D | F1: What_if_count
A2: LDCT-and-Projection-data | B2: /mnt/data-nas/medical_datasets/LDCT-and-Projection-data | C2: CT | D2: 8044937 | E2: =IF(COUNTIF(Sheet14!A:A, A2)>0, 1, 0) -> 0 | F2: =if(E2=1,D2*2,D2) -> 8044937
A3: UCSF-PDGM | B3: /mnt/data-nas/medical_datasets/TCIA/UCSF-PDGM | C3: MRI | D3: 2323927 | E3: =IF(COUNTIF(Sheet14!A:A, A3)>0, 1, 0) -> 1 | F3: =if(E3=1,D3*2,D3) -> 4647854
A4: Endo-FM | B4: /mnt/data-nas/medical_datasets/Endo-FM | C4: Endoscopy | D4: 1831457 | E4: =IF(COUNTIF(Sheet14!A:A, A4)>0, 1, 0) -> 0 | F4: =if(E4=1,D4*2,D4) -> 1831457
A5: Phantom | B5: /mnt/data-nas/medical_datasets/TCIA/Phantom_FDA/dontmove | C5: CT | D5: 1468751 | E5: =IF(COUNTIF(Sheet14!A:A, A5)>0, 1, 0) -> 0 | F5: =if(E5=1,D5*2,D5) -> 1468751
A6: MPILMBB | B6: /mnt/data-nas/medical_datasets/MPILMBB | C6: MRI | D6: 1391255 | E6: =IF(COUNTIF(Sheet14!A:A, A6)>0, 1, 0) -> 1 | F6: =if(E6=1,D6*2,D6) -> 2782510
A7: Advanced-MRI-Breast-Lesions | B7: /mnt/data-nas/vibalcam/datasets/Advanced-MRI-Breast-Lesions | C7: MRI | D7: 1259589 | E7: =IF(COUNTIF(Sheet14!A:A, A7)>0, 1, 0) -> 0 | F7: =if(E7=1,D7*2,D7) -> 1259589
A8: CT-COLONOGRAPHY | B8: /mnt/data-nas/medical_datasets/CT-COLONOGRAPHY | C8: CT | D8: 939871 | E8: =IF(COUNTIF(Sheet14!A:A, A8)>0, 1, 0) -> 0 | F8: =if(E8=1,D8*2,D8) -> 939871
A9: EchoNet-Dynamic | B9: /mnt/data-nas/medical_datasets/EchoNet-Dynamic | C9: Ultrasound | D9: 882309 | E9: =IF(COUNTIF(Sheet14!A:A, A9)>0, 1, 0) -> 0 | F9: =if(E9=1,D9*2,D9) -> 882309
A10: RadImageNet | B10: /mnt/data-nas/medical_datasets/radiology_ai/MR/dontmove | C10: MRI | D10: 672675 | E10: =IF(COUNTIF(Sheet14!A:A, A10)>0, 1, 0) -> 0 | F10: =if(E10=1,D10*2,D10) -> 672675
A11: Quilt-1M | B11: /mnt/data-nas/medical_datasets/Quilt-1M | C11: Microscopy | D11: 653136 | E11: =IF(COUNTIF(Sheet14!A:A, A11)>0, 1, 0) -> 0 | F11: =if(E11=1,D11*2,D11) -> 653136
A12: ISIC-Archive | B12: /mnt/data-nas/medical_datasets/ISIC-Archive | C12: Dermoscopy | D12: 537969 | E12: =IF(COUNTIF(Sheet14!A:A, A12)>0, 1, 0) -> 0 | F12: =if(E12=1,D12*2,D12) -> 537969
A13: ULS23 | B13: /mnt/data-nas/medical_datasets/ULS23 | C13: CT | D13: 480056 | E13: =IF(COUNTIF(Sheet14!A:A, A13)>0, 1, 0) -> 1 | F13: =if(E13=1,D13*2,D13) -> 960112
... A134: LES-AV | B134: /mnt/data-nas/medical_datasets/LES-AV | C134: Fundus | D134: 22 | E134: =IF(COUNTIF(Sheet14!A:A, A134)>0, 1, 0) -> 0 | F134: =if(E134=1,D134*2,D134) -> 22

Sheet Ajay_Processed
A1: File (Server name: File name) | B1: Name | C1: Body Part | D1: Anatomical Area | E1: Modality | F1: Broad Modality | G1: Processed Images | H1: reason | I1: reason | J1: reason | K1: has_data | L1: is_3D | M1: What_if_count
A2: nih-chest-xrays | B2: NIH Chest X-rays | C2: Chest | D2: Chest | E2: X-ray | F2: X-Ray | G2: 356647 | K2: =IF(G2>0,1,0) -> 1 | L2: =IF(COUNTIF(Sheet14!A:A, A2)>0, 1, 0) -> 0 | M2: =if(L2=1,G2*2,G2) -> 356647
A3: LIDC-IDRI | B3: LIDC-IDRI | C3: Chest | D3: Lung | E3: CT | F3: CT | G3: 244527 | K3: =IF(G3>0,1,0) -> 1 | L3: =IF(COUNTIF(Sheet14!A:A, A3)>0, 1, 0) -> 0 | M3: =if(L3=1,G3*2,G3) -> 244527
A4: luna16 | B4: LUNA16 | C4: Chest | D4: Lung | E4: CT | F4: CT | G4: 548 | K4: =IF(G4>0,1,0) -> 1
A5: jsrt | B5: miniJSRT | C5: Chest | D5: Chest | E5: X-ray | F5: X-Ray | G5: 0 | I5: black images | K5: =IF(G5>0,1,0) -> 0
A6: crass12 | B6: CRASS12 | C6: Chest | D6: Clavicle | E6: X-ray | F6: X-Ray | G6: 0 | I6: .mhd | J6: all failed | K6: =IF(G6>0,1,0) -> 0
A7: tuberculosis-chest-xrays-shenzhen | B7: SZ-CXR | C7: Chest | D7: Lung | E7: X-ray | F7: X-Ray | G7: 662 | K7: =IF(G7>0,1,0) -> 1 | L7: =IF(COUNTIF(Sheet14!A:A, A7)>0, 1, 0) -> 0 | M7: =if(L7=1,G7*2,G7) -> 662
A8: fumpe | B8: FUMPE | C8: Chest | D8: Lung | E8: CT | F8: CT | G8: 8792 | K8: =IF(G8>0,1,0) -> 1 | L8: =IF(COUNTIF(Sheet14!A:A, A8)>0, 1, 0) -> 0 | M8: =if(L8=1,G8*2,G8) -> 8792
A9: Pneumothorax_Masks | B9: Pneumothorax Masks X-Ray | C9: Chest | D9: Lung | E9: X-ray | F9: X-Ray | G9: 12047 | K9: =IF(G9>0,1,0) -> 1 | L9: =IF(COUNTIF(Sheet14!A:A, A9)>0, 1, 0) -> 0 | M9: =if(L9=1,G9*2,G9) -> 12047
A10: LNDb | B10: LNDb | C10: Chest | D10: Chest | E10: CT | F10: CT | G10: 0 | I10: .raw | K10: =IF(G10>0,1,0) -> 0
A11: Dataset_BUSI | B11: BUSI | C11: Chest | D11: Chest | E11: Ultrasound | F11: Ultrasound | G11: 1578 | K11: =IF(G11>0,1,0) -> 1 | L11: =IF(COUNTIF(Sheet14!A:A, A11)>0, 1, 0) -> 0 | M11: =if(L11=1,G11*2,G11) -> 1578
A12: PleThora | B12: PleThora | C12: Chest | D12: Chest cavity | E12: CT | F12: CT | G12: 67862 | K12: =IF(G12>0,1,0) -> 1 | L12: =IF(COUNTIF(Sheet14!A:A, A12)>0, 1, 0) -> 1 | M12: =if(L12=1,G12*2,G12) -> 135724
A13: sars_covid_2_ct | B13: SARS-COV-2 Ct-Scan | C13: Chest | D13: Chest | E13: CT | F13: CT | G13: 2481 | K13: =IF(G13>0,1,0) -> 1 | L13: =IF(COUNTIF(Sheet14!A:A, A13)>0, 1, 0) -> 0 | M13: =if(L13=1,G13*2,G13) -> 2481
A14: COVID_CT_COVID-CT | B14: COVID_CT_COVID-CT | C14: Chest | D14: Chest | E14: CT | F14: CT | G14: 1001 | K14: =IF(G14>0,1,0) -> 1 | L14: =IF(COUNTIF(Sheet14!A:A, A14)>0, 1, 0) -> 0 | M14: =if(L14=1,G14*2,G14) -> 1001
A15: coronahack | B15: CoronaHack | C15: Chest | D15: Chest | E15: Cxr | F15: X-Ray | G15: 5933 | K15: =IF(G15>0,1,0) -> 1 | L15: =IF(COUNTIF(Sheet14!A:A, A15)>0, 1, 0) -> 0 | M15: =if(L15=1,G15*2,G15) -> 5933
A16: COVIDGR_1.0/COVIDGR_1.0 | B16: COVIDGR | C16: Chest | D16: Chest | E16: X-ray | F16: X-Ray | G16: 852 | K16: =IF(G16>0,1,0) -> 1 | L16: =IF(COUNTIF(Sheet14!A:A, A16)>0, 1, 0) -> 0 | M16: =if(L16=1,G16*2,G16) -> 852
A17: siim-covid19-detection | B17: SIIM-FISABIO-RSNA COVID-19 | C17: Chest | D17: Chest | E17: X-ray | F17: X-Ray | G17: 7047 | K17: =IF(G17>0,1,0) -> 1 | L17: =IF(COUNTIF(Sheet14!A:A, A17)>0, 1, 0) -> 0 | M17: =if(L17=1,G17*2,G17) -> 7047
A18: WSSS4LUAD | B18: WSSS4LUAD | C18: Chest | D18: Lung | E18: Pathology | F18: Microscopy | G18: 10211 | K18: =IF(G18>0,1,0) -> 1 | L18: =IF(COUNTIF(Sheet14!A:A, A18)>0, 1, 0) -> 0 | M18: =if(L18=1,G18*2,G18) -> 10211
A19: COVID-19_Radiography_Database | B19: COVID-19 CHEST X-RAY DATABASE | C19: Chest | D19: Chest | E19: X-ray | F19: X-Ray | G19: 3886 | K19: =IF(G19>0,1,0) -> 1 | L19: =IF(COUNTIF(Sheet14!A:A, A19)>0, 1, 0) -> 0 | M19: =if(L19=1,G19*2,G19) -> 3886
A20: chest-ctscan/chest-ctscan-images_datasets | B20: Chest CT-Scan images | C20: Chest | D20: Chest | E20: CT | F20: CT | G20: 1000 | K20: =IF(G20>0,1,0) -> 1 | L20: =IF(COUNTIF(Sheet14!A:A, A20)>0, 1, 0) -> 0 | M20: =if(L20=1,G20*2,G20) -> 1000
A21: COVID-19-CT/COVID-19-CT_SCAN_IMAGES_datasets | B21: COVID-19-CT SCAN IMAGES | C21: Chest | D21: Chest | E21: CT | F21: CT | G21: 1404 | K21: =IF(G21>0,1,0) -> 1 | L21: =IF(COUNTIF(Sheet14!A:A, A21)>0, 1, 0) -> 0 | M21: =if(L21=1,G21*2,G21) -> 1404
A22: xray-pd | B22: Chest X-ray PD Dataset | C22: Chest | D22: Chest | E22: X-ray | F22: X-Ray | G22: 4575 | K22: =IF(G22>0,1,0) -> 1 | L22: =IF(COUNTIF(Sheet14!A:A, A22)>0, 1, 0) -> 0 | M22: =if(L22=1,G22*2,G22) -> 4575
A23: ChinaSet_AllFIles | B23: Shenzhen chest X-ray set | C23: Chest | F23: X-Ray | G23: 662 | K23: =IF(G23>0,1,0) -> 1 | L23: =IF(COUNTIF(Sheet14!A:A, A23)>0, 1, 0) -> 0 | M23: =if(L23=1,G23*2,G23) -> 662
A24: mvseg2023 | B24: MVSeg-3DTEE 2023 | C24: Chest | D24: Chest | E24: Us | F24: Ultrasound | G24: 77746 | K24: =IF(G24>0,1,0) -> 1 | L24: =IF(COUNTIF(Sheet14!A:A, A24)>0, 1, 0) -> 1 | M24: =if(L24=1,G24*2,G24) -> 155492
A25: AIIB23 | B25: AIIB23 | C25: Chest | D25: Chest | E25: CT | F25: CT | G25: 138093 | K25: =IF(G25>0,1,0) -> 1 | L25: =IF(COUNTIF(Sheet14!A:A, A25)>0, 1, 0) -> 1 | M25: =if(L25=1,G25*2,G25) -> 276186
A26: LNQ_2023 | B26: LNQ 2023 | C26: Chest | D26: Chest | E26: CT | F26: CT | G26: 242202 | K26: =IF(G26>0,1,0) -> 1 | L26: =IF(COUNTIF(Sheet14!A:A, A26)>0, 1, 0) -> 1 | M26: =if(L26=1,G26*2,G26) -> 484404
A27: LungHist700 | B27: LungHist700 | C27: Chest | D27: Lung | E27: Pathological images | F27: Microscopy | G27: 691 | K27: =IF(G27>0,1,0) -> 1 | L27: =IF(COUNTIF(Sheet14!A:A, A27)>0, 1, 0) -> 0 | M27: =if(L27=1,G27*2,G27) -> 691
A28: VESSEL12 | B28: VESSEL12 | C28: Chest | D28: Lung | E28: CT | F28: CT | G28: 16737 | K28: =IF(G28>0,1,0) -> 1 | L28: =IF(COUNTIF(Sheet14!A:A, A28)>0, 1, 0) -> 1 | M28: =if(L28=1,G28*2,G28) -> 33474
A29: mias-mammography | B29: MIAS | C29: Chest | D29: Breast | E29: X-ray | F29: X-Ray | G29: 322 | K29: =IF(G29>0,1,0) -> 1 | L29: =IF(COUNTIF(Sheet14!A:A, A29)>0, 1, 0) -> 0 | M29: =if(L29=1,G29*2,G29) -> 322
A30: DeepLesion | B30: DeepLesion | C30: Chest | E30: CT | F30: CT | G30: 960240 | K30: =IF(G30>0,1,0) -> 1 | L30: =IF(COUNTIF(Sheet14!A:A, A30)>0, 1, 0) -> 0 | M30: =if(L30=1,G30*2,G30) -> 960240
A31: BreakHis | B31: BreakHis | C31: Chest | D31: Breast | E31: Histopathology (microscopy) | F31: Microscopy | G31: 7909 | K31: =IF(G31>0,1,0) -> 1 | L31: =IF(COUNTIF(Sheet14!A:A, A31)>0, 1, 0) -> 0 | M31: =if(L31=1,G31*2,G31) -> 7909
A32: bcfpp | B32: Breast Cancer CT | C32: Chest | D32: Breast | E32: CT | F32: CT | G32: 0 | I32: .jlb | J32: only 1 and that failed | K32: =IF(G32>0,1,0) -> 0
A33: BUS-UCLM | B33: BUS-UCLM | C33: Chest | D33: Breast | E33: Ultrasound | F33: Ultrasound | G33: 683 | K33: =IF(G33>0,1,0) -> 1 | L33: =IF(COUNTIF(Sheet14!A:A, A33)>0, 1, 0) -> 0 | M33: =if(L33=1,G33*2,G33) -> 683
A34: INbreast | B34: INbreast | C34: Chest | D34: Breast | F34: X-Ray | G34: 410 | K34: =IF(G34>0,1,0) -> 1 | L34: =IF(COUNTIF(Sheet14!A:A, A34)>0, 1, 0) -> 0 | M34: =if(L34=1,G34*2,G34) -> 410
A35: Mini-DDSM | B35: Mini-DDSM | C35: Chest | D35: Breast | E35: Mammography | F35: X-Ray | G35: 18682 | K35: =IF(G35>0,1,0) -> 1 | L35: =IF(COUNTIF(Sheet14!A:A, A35)>0, 1, 0) -> 0 | M35: =if(L35=1,G35*2,G35) -> 18682
A36: MITOS-ATYPIA-14 | B36: MITOS-ATYPIA-14 | C36: Chest | D36: Breast | E36: Histopathology | F36: Microscopy | G36: 11172 | K36: =IF(G36>0,1,0) -> 1 | L36: =IF(COUNTIF(Sheet14!A:A, A36)>0, 1, 0) -> 0 | M36: =if(L36=1,G36*2,G36) -> 11172
A37: Post-NAT-BRCA | B37: Post-NAT-BRCA | C37: Chest | D37: Breast | E37: Histopathology | F37: Microscopy | G37: 96 | K37: =IF(G37>0,1,0) -> 1 | L37: =IF(COUNTIF(Sheet14!A:A, A37)>0, 1, 0) -> 0 | M37: =if(L37=1,G37*2,G37) -> 96
A38: sln-breast | B38: SLN-Breast | C38: Chest | D38: Breast | E38: Histopathology | F38: Microscopy | G38: 130 | K38: =IF(G38>0,1,0) -> 1 | L38: =IF(COUNTIF(Sheet14!A:A, A38)>0, 1, 0) -> 0 | M38: =if(L38=1,G38*2,G38) -> 130
A39: TUPAC | B39: TUPAC | C39: Chest | D39: Breast | E39: Histopathology (H&E) | F39: Microscopy | G39: 34 | K39: =IF(G39>0,1,0) -> 1 | L39: =IF(COUNTIF(Sheet14!A:A, A39)>0, 1, 0) -> 0 | M39: =if(L39=1,G39*2,G39) -> 34
A40: Airway | B40: Airway | C40: Chest | D40: Lungs | E40: CT | F40: CT | G40: 13138 | K40: =IF(G40>0,1,0) -> 1 | L40: =IF(COUNTIF(Sheet14!A:A, A40)>0, 1, 0) -> 1 | M40: =if(L40=1,G40*2,G40) -> 26276
...

Sheet Sheet14
A1: directory_name | B1: directory_path
A2: 3D-MR-MS | B2: /mnt/data-nas/medical_datasets/mixed_modalities/3D-MR-MS
A3: 3DLowerLimb | B3: /mnt/data-nas/medical_datasets/ajay_processed/3DLowerLimb
A4: 7-Tesla | B4: /mnt/data-nas/medical_datasets/BIOVFM-PNG/7-Tesla
A5: ABIDE | B5: /mnt/data-nas/medical_datasets/BIOVFM-PNG/ABIDE
A6: ACDC | B6: /mnt/data-nas/medical_datasets/ajay_processed/ACDC
A7: ACOUSLIC | B7: /mnt/data-nas/medical_datasets/ajay_processed/ACOUSLIC
A8: ACPI_DU_LaBar | B8: /mnt/data-nas/medical_datasets/ajay_processed/ACPI_DU_LaBar
A9: ACPI_MTA | B9: /mnt/data-nas/medical_datasets/ajay_processed/ACPI_MTA
A10: ACPI_NYU | B10: /mnt/data-nas/medical_datasets/ajay_processed/ACPI_NYU
A11: ACRIN_6688 | B11: /mnt/data-nas/medical_datasets/ajay_processed/ACRIN_6688
A12: ADHD-200 | B12: /mnt/data-nas/medical_datasets/BIOVFM-PNG/ADHD-200
... A169: xVertSeg | B169: /mnt/data-nas/medical_datasets/ajay_processed/xVertSeg

Sheet Website
A1: File (Server name: File name) | B1: Name | C1: Body Part | D1: Anatomical Area | E1: Modality | F1: Broad Modality | G1: Processed Images | H1: Dataset Size | I1: Link | J1: Website Modality
A2: nih-chest-xrays | B2: NIH Chest X-rays | C2: Chest | D2: Chest | E2: X-ray | F2: X-Ray | G2: 356647 | H2: 112120 | I2: =IFERROR(__xludf.DUMMYFUNCTION("XLOOKUP(B2, IMPORTRANGE(""https://docs.google.com/spreadsheets/d/1UBtmuaUf7_Fv957LMBmn6lMadUM-z7scKS8El4i3Thk/edit?usp=sharing"", ""sheet1!J:J""), IMPORTRANGE(""https://docs.google.com/spreadsheets/d/1UBtmuaUf7_Fv957LMBmn6lMadUM-z7scKS8El4i3Thk/edit?usp=s"&"haring"", ""sheet1!AA:AA""), 0)"),"https://www.kaggle.com/datasets/nih-chest-xrays/data") -> https://www.kaggle.com/datasets/nih-chest-xrays/data | J2: =IF(OR(LOWER(F2)="mri", LOWER(F2)="ultrasound", LOWER(F2)="endoscopy", LOWER(F2)="dermoscopy", LOWER(F2)="fundus", LOWER(F2)="octa", LOWER(F2)="oct"), F2, IF(OR(LOWER(E2)="microscopy", LOWER(E2)="histopathology", LOWER(E2)="pathology", LOWER(E2)="ct", LOWER(E2)="pet", LOWER(E2)="x-ray", LOWER(E2)="mammography"), E2, "")) -> X-ray
A3: LIDC-IDRI | B3: LIDC-IDRI | C3: Chest | D3: Lung | E3: CT | F3: CT | G3: 244527 | H3: 244527 | I3: =IFERROR(__xludf.DUMMYFUNCTION("XLOOKUP(B3, IMPORTRANGE(""https://docs.google.com/spreadsheets/d/1UBtmuaUf7_Fv957LMBmn6lMadUM-z7scKS8El4i3Thk/edit?usp=sharing"", ""sheet1!J:J""), IMPORTRANGE(""https://docs.google.com/spreadsheets/d/1UBtmuaUf7_Fv957LMBmn6lMadUM-z7scKS8El4i3Thk/edit?usp=s"&"haring"", ""sheet1!AA:AA""), 0)"),"https://www.cancerimagingarchive.net/collection/lidc-idri/") -> https://www.cancerimagingarchive.net/collection/lidc-idri/ | J3: =IF(OR(F3="MRI", F3="Ultrasound", F3="Endoscopy", F3="Dermoscopy", F3="Fundus", F3="OCTA", F3="OCT"), F3, IF(OR(E3="Microscopy", E3="Histopathology", E3="Pathology", E3="CT", E3="PET", E3="X-Ray", E3="Mammography"), E3, "")) -> CT
A4: tuberculosis-chest-xrays-shenzhen | B4: SZ-CXR | C4: Chest | D4: Lung | E4: X-ray | F4: X-Ray | G4: 662 | H4: 662 | I4: =IFERROR(__xludf.DUMMYFUNCTION("XLOOKUP(B4, IMPORTRANGE(""https://docs.google.com/spreadsheets/d/1UBtmuaUf7_Fv957LMBmn6lMadUM-z7scKS8El4i3Thk/edit?usp=sharing"", ""sheet1!J:J""), IMPORTRANGE(""https://docs.google.com/spreadsheets/d/1UBtmuaUf7_Fv957LMBmn6lMadUM-z7scKS8El4i3Thk/edit?usp=s"&"haring"", ""sheet1!AA:AA""), 0)"),"https://www.kaggle.com/datasets/raddar/tuberculosis-chest-xrays-shenzhen") -> https://www.kaggle.com/datasets/raddar/tuberculosis-chest-xrays-shenzhen | J4: =IF(OR(F4="MRI", F4="Ultrasound", F4="Endoscopy", F4="Dermoscopy", F4="Fundus", F4="OCTA", F4="OCT"), F4, IF(OR(E4="Microscopy", E4="Histopathology", E4="Pathology", E4="CT", E4="PET", E4="X-Ray", E4="Mammography"), E4, "")) -> X-ray
A5: fumpe | B5: FUMPE | C5: Chest | D5: Lung | E5: CT | F5: CT | G5: 8792 | I5: =IFERROR(__xludf.DUMMYFUNCTION("XLOOKUP(B5, IMPORTRANGE(""https://docs.google.com/spreadsheets/d/1UBtmuaUf7_Fv957LMBmn6lMadUM-z7scKS8El4i3Thk/edit?usp=sharing"", ""sheet1!J:J""), IMPORTRANGE(""https://docs.google.com/spreadsheets/d/1UBtmuaUf7_Fv957LMBmn6lMadUM-z7scKS8El4i3Thk/edit?usp=s"&"haring"", ""sheet1!AA:AA""), 0)"),"https://figshare.com/collections/FUMPE/4107803/1") -> https://figshare.com/collections/FUMPE/4107803/1 | J5: =IF(OR(F5="MRI", F5="Ultrasound", F5="Endoscopy", F5="Dermoscopy", F5="Fundus", F5="OCTA", F5="OCT"), F5, IF(OR(E5="Microscopy", E5="Histopathology", E5="Pathology", E5="CT", E5="PET", E5="X-Ray", E5="Mammography"), E5, "")) -> CT
A6: Pneumothorax_Masks | B6: Pneumothorax Masks X-Ray | C6: Chest | D6: Lung | E6: X-ray | F6: X-Ray | G6: 12047 | H6: 12047 | I6: =IFERROR(__xludf.DUMMYFUNCTION("XLOOKUP(B6, IMPORTRANGE(""https://docs.google.com/spreadsheets/d/1UBtmuaUf7_Fv957LMBmn6lMadUM-z7scKS8El4i3Thk/edit?usp=sharing"", ""sheet1!J:J""), IMPORTRANGE(""https://docs.google.com/spreadsheets/d/1UBtmuaUf7_Fv957LMBmn6lMadUM-z7scKS8El4i3Thk/edit?usp=s"&"haring"", ""sheet1!AA:AA""), 0)"),"https://www.kaggle.com/datasets/vbookshelf/pneumothorax-chest-xray-images-and-masks/data") -> https://www.kaggle.com/datasets/vbookshelf/pneumothorax-chest-xray-images-and-masks/data | J6: =IF(OR(F6="MRI", F6="Ultrasound", F6="Endoscopy", F6="Dermoscopy", F6="Fundus", F6="OCTA", F6="OCT"), F6, IF(OR(E6="Microscopy", E6="Histopathology", E6="Pathology", E6="CT", E6="PET", E6="X-Ray", E6="Mammography"), E6, "")) -> X-ray
A7: Dataset_BUSI | B7: BUSI | C7: Chest | D7: Chest | E7: Ultrasound | F7: Ultrasound | G7: 1578 | H7: 780 | I7: =IFERROR(__xludf.DUMMYFUNCTION("XLOOKUP(B7, IMPORTRANGE(""https://docs.google.com/spreadsheets/d/1UBtmuaUf7_Fv957LMBmn6lMadUM-z7scKS8El4i3Thk/edit?usp=sharing"", ""sheet1!J:J""), IMPORTRANGE(""https://docs.google.com/spreadsheets/d/1UBtmuaUf7_Fv957LMBmn6lMadUM-z7scKS8El4i3Thk/edit?usp=s"&"haring"", ""sheet1!AA:AA""), 0)"),"https://scholar.cu.edu.eg/?q=afahmy/pages/dataset") -> https://scholar.cu.edu.eg/?q=afahmy/pages/dataset | J7: =IF(OR(F7="MRI", F7="Ultrasound", F7="Endoscopy", F7="Dermoscopy", F7="Fundus", F7="OCTA", F7="OCT"), F7, IF(OR(E7="Microscopy", E7="Histopathology", E7="Pathology", E7="CT", E7="PET", E7="X-Ray", E7="Mammography"), E7, "")) -> Ultrasound
A8: PleThora | B8: PleThora | C8: Chest | D8: Chest cavity | E8: CT | F8: CT | G8: 67862 | H8: 402 | I8: =IFERROR(__xludf.DUMMYFUNCTION("XLOOKUP(B8, IMPORTRANGE(""https://docs.google.com/spreadsheets/d/1UBtmuaUf7_Fv957LMBmn6lMadUM-z7scKS8El4i3Thk/edit?usp=sharing"", ""sheet1!J:J""), IMPORTRANGE(""https://docs.google.com/spreadsheets/d/1UBtmuaUf7_Fv957LMBmn6lMadUM-z7scKS8El4i3Thk/edit?usp=s"&"haring"", ""sheet1!AA:AA""), 0)"),"https://www.cancerimagingarchive.net/analysis-result/plethora") -> https://www.cancerimagingarchive.net/analysis-result/plethora | J8: =IF(OR(F8="MRI", F8="Ultrasound", F8="Endoscopy", F8="Dermoscopy", F8="Fundus", F8="OCTA", F8="OCT"), F8, IF(OR(E8="Microscopy", E8="Histopathology", E8="Pathology", E8="CT", E8="PET", E8="X-Ray", E8="Mammography"), E8, "")) -> CT
A9: sars_covid_2_ct | B9: SARS-COV-2 Ct-Scan | C9: Chest | D9: Chest | E9: CT | F9: CT | G9: 2481 | H9: 2482 | I9: =IFERROR(__xludf.DUMMYFUNCTION("XLOOKUP(B9, IMPORTRANGE(""https://docs.google.com/spreadsheets/d/1UBtmuaUf7_Fv957LMBmn6lMadUM-z7scKS8El4i3Thk/edit?usp=sharing"", ""sheet1!J:J""), IMPORTRANGE(""https://docs.google.com/spreadsheets/d/1UBtmuaUf7_Fv957LMBmn6lMadUM-z7scKS8El4i3Thk/edit?usp=s"&"haring"", ""sheet1!AA:AA""), 0)"),"https://www.kaggle.com/datasets/plameneduardo/sarscov2-ctscan-dataset") -> https://www.kaggle.com/datasets/plameneduardo/sarscov2-ctscan-dataset | J9: =IF(OR(F9="MRI", F9="Ultrasound", F9="Endoscopy", F9="Dermoscopy", F9="Fundus", F9="OCTA", F9="OCT"), F9, IF(OR(E9="Microscopy", E9="Histopathology", E9="Pathology", E9="CT", E9="PET", E9="X-Ray", E9="Mammography"), E9, "")) -> CT
A10: COVID_CT_COVID-CT | B10: COVID_CT_COVID-CT | C10: Chest | D10: Chest | E10: CT | F10: CT | G10: 1001 | I10: =IFERROR(__xludf.DUMMYFUNCTION("XLOOKUP(B10, IMPORTRANGE(""https://docs.google.com/spreadsheets/d/1UBtmuaUf7_Fv957LMBmn6lMadUM-z7scKS8El4i3Thk/edit?usp=sharing"", ""sheet1!J:J""), IMPORTRANGE(""https://docs.google.com/spreadsheets/d/1UBtmuaUf7_Fv957LMBmn6lMadUM-z7scKS8El4i3Thk/edit?usp="&"sharing"", ""sheet1!AA:AA""), 0)"),"https://tianchi.aliyun.com/dataset/106604") -> https://tianchi.aliyun.com/dataset/106604 | J10: =IF(OR(F10="MRI", F10="Ultrasound", F10="Endoscopy", F10="Dermoscopy", F10="Fundus", F10="OCTA", F10="OCT"), F10, IF(OR(E10="Microscopy", E10="Histopathology", E10="Pathology", E10="CT", E10="PET", E10="X-Ray", E10="Mammography"), E10, "")) -> CT
A11: coronahack | B11: CoronaHack | C11: Chest | D11: Chest | E11: Cxr | F11: X-Ray | G11: 5933 | H11: 5800 | I11: =IFERROR(__xludf.DUMMYFUNCTION("XLOOKUP(B11, IMPORTRANGE(""https://docs.google.com/spreadsheets/d/1UBtmuaUf7_Fv957LMBmn6lMadUM-z7scKS8El4i3Thk/edit?usp=sharing"", ""sheet1!J:J""), IMPORTRANGE(""https://docs.google.com/spreadsheets/d/1UBtmuaUf7_Fv957LMBmn6lMadUM-z7scKS8El4i3Thk/edit?usp="&"sharing"", ""sheet1!AA:AA""), 0)"),"https://www.kaggle.com/datasets/praveengovi/coronahack-chest-xraydataset/data") -> https://www.kaggle.com/datasets/praveengovi/coronahack-chest-xraydataset/data | J11: X-ray
A12: COVIDGR_1.0/COVIDGR_1.0 | B12: COVIDGR | C12: Chest | D12: Chest | E12: X-ray | F12: X-Ray | G12: 852 | H12: 852 | I12: =IFERROR(__xludf.DUMMYFUNCTION("XLOOKUP(B12, IMPORTRANGE(""https://docs.google.com/spreadsheets/d/1UBtmuaUf7_Fv957LMBmn6lMadUM-z7scKS8El4i3Thk/edit?usp=sharing"", ""sheet1!J:J""), IMPORTRANGE(""https://docs.google.com/spreadsheets/d/1UBtmuaUf7_Fv957LMBmn6lMadUM-z7scKS8El4i3Thk/edit?usp="&"sharing"", ""sheet1!AA:AA""), 0)"),"https://github.com/ari-dasci/covidgr") -> https://github.com/ari-dasci/covidgr | J12: =IF(OR(F12="MRI", F12="Ultrasound", F12="Endoscopy", F12="Dermoscopy", F12="Fundus", F12="OCTA", F12="OCT"), F12, IF(OR(E12="Microscopy", E12="Histopathology", E12="Pathology", E12="CT", E12="PET", E12="X-Ray", E12="Mammography"), E12, "")) -> X-ray
A13: siim-covid19-detection | B13: SIIM-FISABIO-RSNA COVID-19 | C13: Chest | D13: Chest | E13: X-ray | F13: X-Ray | G13: 7047 | H13: 6334 | I13: =IFERROR(__xludf.DUMMYFUNCTION("XLOOKUP(B13, IMPORTRANGE(""https://docs.google.com/spreadsheets/d/1UBtmuaUf7_Fv957LMBmn6lMadUM-z7scKS8El4i3Thk/edit?usp=sharing"", ""sheet1!J:J""), IMPORTRANGE(""https://docs.google.com/spreadsheets/d/1UBtmuaUf7_Fv957LMBmn6lMadUM-z7scKS8El4i3Thk/edit?usp="&"sharing"", ""sheet1!AA:AA""), 0)"),"https://www.kaggle.com/competitions/siim-covid19-detection/data") -> https://www.kaggle.com/competitions/siim-covid19-detection/data | J13: =IF(OR(F13="MRI", F13="Ultrasound", F13="Endoscopy", F13="Dermoscopy", F13="Fundus", F13="OCTA", F13="OCT"), F13, IF(OR(E13="Microscopy", E13="Histopathology", E13="Pathology", E13="CT", E13="PET", E13="X-Ray", E13="Mammography"), E13, "")) -> X-ray
A14: WSSS4LUAD | B14: WSSS4LUAD | C14: Chest | D14: Lung | E14: Pathology | F14: Microscopy | G14: 10211 | H14: 10211 | I14: =IFERROR(__xludf.DUMMYFUNCTION("XLOOKUP(B14, IMPORTRANGE(""https://docs.google.com/spreadsheets/d/1UBtmuaUf7_Fv957LMBmn6lMadUM-z7scKS8El4i3Thk/edit?usp=sharing"", ""sheet1!J:J""), IMPORTRANGE(""https://docs.google.com/spreadsheets/d/1UBtmuaUf7_Fv957LMBmn6lMadUM-z7scKS8El4i3Thk/edit?usp="&"sharing"", ""sheet1!AA:AA""), 0)"),"https://wsss4luad.grand-challenge.org/WSSS4LUAD/") -> https://wsss4luad.grand-challenge.org/WSSS4LUAD/ | J14: =IF(OR(F14="MRI", F14="Ultrasound", F14="Endoscopy", F14="Dermoscopy", F14="Fundus", F14="OCTA", F14="OCT"), F14, IF(OR(E14="Microscopy", E14="Histopathology", E14="Pathology", E14="CT", E14="PET", E14="X-Ray", E14="Mammography"), E14, "")) -> Pathology
A15: COVID-19_Radiography_Database | B15: COVID-19 CHEST X-RAY DATABASE | C15: Chest | D15: Chest | E15: X-ray | F15: X-Ray | G15: 3886 | H15: 1341 | I15: =IFERROR(__xludf.DUMMYFUNCTION("XLOOKUP(B15, IMPORTRANGE(""https://docs.google.com/spreadsheets/d/1UBtmuaUf7_Fv957LMBmn6lMadUM-z7scKS8El4i3Thk/edit?usp=sharing"", ""sheet1!J:J""), IMPORTRANGE(""https://docs.google.com/spreadsheets/d/1UBtmuaUf7_Fv957LMBmn6lMadUM-z7scKS8El4i3Thk/edit?usp="&"sharing"", ""sheet1!AA:AA""), 0)"),"https://www.heywhale.com/mw/dataset/6027caee891f960015c863d7/content") -> https://www.heywhale.com/mw/dataset/6027caee891f960015c863d7/content | J15: =IF(OR(F15="MRI", F15="Ultrasound", F15="Endoscopy", F15="Dermoscopy", F15="Fundus", F15="OCTA", F15="OCT"), F15, IF(OR(E15="Microscopy", E15="Histopathology", E15="Pathology", E15="CT", E15="PET", E15="X-Ray", E15="Mammography"), E15, "")) -> X-ray
A16: chest-ctscan/chest-ctscan-images_datasets | B16: Chest CT-Scan images | C16: Chest | D16: Chest | E16: CT | F16: CT | G16: 1000 | I16: =IFERROR(__xludf.DUMMYFUNCTION("XLOOKUP(B16, IMPORTRANGE(""https://docs.google.com/spreadsheets/d/1UBtmuaUf7_Fv957LMBmn6lMadUM-z7scKS8El4i3Thk/edit?usp=sharing"", ""sheet1!J:J""), IMPORTRANGE(""https://docs.google.com/spreadsheets/d/1UBtmuaUf7_Fv957LMBmn6lMadUM-z7scKS8El4i3Thk/edit?usp="&"sharing"", ""sheet1!AA:AA""), 0)"),"https://tianchi.aliyun.com/dataset/93929") -> https://tianchi.aliyun.com/dataset/93929 | J16: =IF(OR(F16="MRI", F16="Ultrasound", F16="Endoscopy", F16="Dermoscopy", F16="Fundus", F16="OCTA", F16="OCT"), F16, IF(OR(E16="Microscopy", E16="Histopathology", E16="Pathology", E16="CT", E16="PET", E16="X-Ray", E16="Mammography"), E16, "")) -> CT
A17: COVID-19-CT/COVID-19-CT_SCAN_IMAGES_datasets | B17: COVID-19-CT SCAN IMAGES | C17: Chest | D17: Chest | E17: CT | F17: CT | G17: 1404 | I17: =IFERROR(__xludf.DUMMYFUNCTION("XLOOKUP(B17, IMPORTRANGE(""https://docs.google.com/spreadsheets/d/1UBtmuaUf7_Fv957LMBmn6lMadUM-z7scKS8El4i3Thk/edit?usp=sharing"", ""sheet1!J:J""), IMPORTRANGE(""https://docs.google.com/spreadsheets/d/1UBtmuaUf7_Fv957LMBmn6lMadUM-z7scKS8El4i3Thk/edit?usp="&"sharing"", ""sheet1!AA:AA""), 0)"),"https://tianchi.aliyun.com/dataset/93666") -> https://tianchi.aliyun.com/dataset/93666 | J17: =IF(OR(F17="MRI", F17="Ultrasound", F17="Endoscopy", F17="Dermoscopy", F17="Fundus", F17="OCTA", F17="OCT"), F17, IF(OR(E17="Microscopy", E17="Histopathology", E17="Pathology", E17="CT", E17="PET", E17="X-Ray", E17="Mammography"), E17, "")) -> CT
A18: xray-pd | B18: Chest X-ray PD Dataset | C18: Chest | D18: Chest | E18: X-ray | F18: X-Ray | G18: 4575 | H18: 4575 | I18: =IFERROR(__xludf.DUMMYFUNCTION("XLOOKUP(B18, IMPORTRANGE(""https://docs.google.com/spreadsheets/d/1UBtmuaUf7_Fv957LMBmn6lMadUM-z7scKS8El4i3Thk/edit?usp=sharing"", ""sheet1!J:J""), IMPORTRANGE(""https://docs.google.com/spreadsheets/d/1UBtmuaUf7_Fv957LMBmn6lMadUM-z7scKS8El4i3Thk/edit?usp="&"sharing"", ""sheet1!AA:AA""), 0)"),"https://data.mendeley.com/datasets/jctsfj2sfn/1") -> https://data.mendeley.com/datasets/jctsfj2sfn/1 | J18: =IF(OR(F18="MRI", F18="Ultrasound", F18="Endoscopy", F18="Dermoscopy", F18="Fundus", F18="OCTA", F18="OCT"), F18, IF(OR(E18="Microscopy", E18="Histopathology", E18="Pathology", E18="CT", E18="PET", E18="X-Ray", E18="Mammography"), E18, "")) -> X-ray
A19: ChinaSet_AllFIles | B19: Shenzhen chest X-ray set | C19: Chest | D19: Chest | E19: X-Ray | F19: X-Ray | G19: 662 | H19: 662 | I19: =IFERROR(__xludf.DUMMYFUNCTION("XLOOKUP(B19, IMPORTRANGE(""https://docs.google.com/spreadsheets/d/1UBtmuaUf7_Fv957LMBmn6lMadUM-z7scKS8El4i3Thk/edit?usp=sharing"", ""sheet1!J:J""), IMPORTRANGE(""https://docs.google.com/spreadsheets/d/1UBtmuaUf7_Fv957LMBmn6lMadUM-z7scKS8El4i3Thk/edit?usp="&"sharing"", ""sheet1!AA:AA""), 0)"),"https://lhncbc.nlm.nih.gov/LHC-downloads/downloads.html#tuberculosis-image-data-sets") -> https://lhncbc.nlm.nih.gov/LHC-downloads/downloads.html#tuberculosis-image-data-sets | J19: X-ray
A20: mvseg2023 | B20: MVSeg-3DTEE 2023 | C20: Chest | D20: Chest | E20: Us | F20: Ultrasound | G20: 77746 | H20: 150 | I20: =IFERROR(__xludf.DUMMYFUNCTION("XLOOKUP(B20, IMPORTRANGE(""https://docs.google.com/spreadsheets/d/1UBtmuaUf7_Fv957LMBmn6lMadUM-z7scKS8El4i3Thk/edit?usp=sharing"", ""sheet1!J:J""), IMPORTRANGE(""https://docs.google.com/spreadsheets/d/1UBtmuaUf7_Fv957LMBmn6lMadUM-z7scKS8El4i3Thk/edit?usp="&"sharing"", ""sheet1!AA:AA""), 0)"),"https://www.synapse.org/#!Synapse:syn51186045/wiki/621356") -> https://www.synapse.org/#!Synapse:syn51186045/wiki/621356 | J20: =IF(OR(F20="MRI", F20="Ultrasound", F20="Endoscopy", F20="Dermoscopy", F20="Fundus", F20="OCTA", F20="OCT"), F20, IF(OR(E20="Microscopy", E20="Histopathology", E20="Pathology", E20="CT", E20="PET", E20="X-Ray", E20="Mammography"), E20, "")) -> Ultrasound
A21: AIIB23 | B21: AIIB23 | C21: Chest | D21: Chest | E21: CT | F21: CT | G21: 138093 | H21: 285 | I21: =IFERROR(__xludf.DUMMYFUNCTION("XLOOKUP(B21, IMPORTRANGE(""https://docs.google.com/spreadsheets/d/1UBtmuaUf7_Fv957LMBmn6lMadUM-z7scKS8El4i3Thk/edit?usp=sharing"", ""sheet1!J:J""), IMPORTRANGE(""https://docs.google.com/spreadsheets/d/1UBtmuaUf7_Fv957LMBmn6lMadUM-z7scKS8El4i3Thk/edit?usp="&"sharing"", ""sheet1!AA:AA""), 0)"),"https://codalab.lisn.upsaclay.fr/competitions/13238") -> https://codalab.lisn.upsaclay.fr/competitions/13238 | J21: =IF(OR(F21="MRI", F21="Ultrasound", F21="Endoscopy", F21="Dermoscopy", F21="Fundus", F21="OCTA", F21="OCT"), F21, IF(OR(E21="Microscopy", E21="Histopathology", E21="Pathology", E21="CT", E21="PET", E21="X-Ray", E21="Mammography"), E21, "")) -> CT
A22: LNQ_2023 | B22: LNQ 2023 | C22: Chest | D22: Chest | E22: CT | F22: CT | G22: 242202 | I22: =IFERROR(__xludf.DUMMYFUNCTION("XLOOKUP(B22, IMPORTRANGE(""https://docs.google.com/spreadsheets/d/1UBtmuaUf7_Fv957LMBmn6lMadUM-z7scKS8El4i3Thk/edit?usp=sharing"", ""sheet1!J:J""), IMPORTRANGE(""https://docs.google.com/spreadsheets/d/1UBtmuaUf7_Fv957LMBmn6lMadUM-z7scKS8El4i3Thk/edit?usp="&"sharing"", ""sheet1!AA:AA""), 0)"),"https://lnq2023.grand-challenge.org/lnq2023/") -> https://lnq2023.grand-challenge.org/lnq2023/ | J22: =IF(OR(F22="MRI", F22="Ultrasound", F22="Endoscopy", F22="Dermoscopy", F22="Fundus", F22="OCTA", F22="OCT"), F22, IF(OR(E22="Microscopy", E22="Histopathology", E22="Pathology", E22="CT", E22="PET", E22="X-Ray", E22="Mammography"), E22, "")) -> CT
A23: LungHist700 | B23: LungHist700 | C23: Chest | D23: Lung | E23: Pathological images | F23: Microscopy | G23: 691 | H23: 691 | I23: =IFERROR(__xludf.DUMMYFUNCTION("XLOOKUP(B23, IMPORTRANGE(""https://docs.google.com/spreadsheets/d/1UBtmuaUf7_Fv957LMBmn6lMadUM-z7scKS8El4i3Thk/edit?usp=sharing"", ""sheet1!J:J""), IMPORTRANGE(""https://docs.google.com/spreadsheets/d/1UBtmuaUf7_Fv957LMBmn6lMadUM-z7scKS8El4i3Thk/edit?usp="&"sharing"", ""sheet1!AA:AA""), 0)"),"https://www.nature.com/articles/s41597-024-03944-3") -> https://www.nature.com/articles/s41597-024-03944-3 | J23: Pathology
A24: VESSEL12 | B24: VESSEL12 | C24: Chest | D24: Lung | E24: CT | F24: CT | G24: 16737 | I24: =IFERROR(__xludf.DUMMYFUNCTION("XLOOKUP(B24, IMPORTRANGE(""https://docs.google.com/spreadsheets/d/1UBtmuaUf7_Fv957LMBmn6lMadUM-z7scKS8El4i3Thk/edit?usp=sharing"", ""sheet1!J:J""), IMPORTRANGE(""https://docs.google.com/spreadsheets/d/1UBtmuaUf7_Fv957LMBmn6lMadUM-z7scKS8El4i3Thk/edit?usp="&"sharing"", ""sheet1!AA:AA""), 0)"),"https://vessel12.grand-challenge.org/") -> https://vessel12.grand-challenge.org/ | J24: =IF(OR(F24="MRI", F24="Ultrasound", F24="Endoscopy", F24="Dermoscopy", F24="Fundus", F24="OCTA", F24="OCT"), F24, IF(OR(E24="Microscopy", E24="Histopathology", E24="Pathology", E24="CT", E24="PET", E24="X-Ray", E24="Mammography"), E24, "")) -> CT
A25: mias-mammography | B25: MIAS | C25: Chest | D25: Breast | E25: X-ray | F25: X-Ray | G25: 322 | H25: 322 | I25: =IFERROR(__xludf.DUMMYFUNCTION("XLOOKUP(B25, IMPORTRANGE(""https://docs.google.com/spreadsheets/d/1UBtmuaUf7_Fv957LMBmn6lMadUM-z7scKS8El4i3Thk/edit?usp=sharing"", ""sheet1!J:J""), IMPORTRANGE(""https://docs.google.com/spreadsheets/d/1UBtmuaUf7_Fv957LMBmn6lMadUM-z7scKS8El4i3Thk/edit?usp="&"sharing"", ""sheet1!AA:AA""), 0)"),"https://doi.org/10.17863/CAM.105113") -> https://doi.org/10.17863/CAM.105113 | J25: =IF(OR(F25="MRI", F25="Ultrasound", F25="Endoscopy", F25="Dermoscopy", F25="Fundus", F25="OCTA", F25="OCT"), F25, IF(OR(E25="Microscopy", E25="Histopathology", E25="Pathology", E25="CT", E25="PET", E25="X-Ray", E25="Mammography"), E25, "")) -> X-ray
A26: DeepLesion | B26: DeepLesion | C26: Chest | D26: Chest | E26: CT | F26: CT | G26: 960240 | H26: 32000 | I26: =IFERROR(__xludf.DUMMYFUNCTION("XLOOKUP(B26, IMPORTRANGE(""https://docs.google.com/spreadsheets/d/1UBtmuaUf7_Fv957LMBmn6lMadUM-z7scKS8El4i3Thk/edit?usp=sharing"", ""sheet1!J:J""), IMPORTRANGE(""https://docs.google.com/spreadsheets/d/1UBtmuaUf7_Fv957LMBmn6lMadUM-z7scKS8El4i3Thk/edit?usp="&"sharing"", ""sheet1!AA:AA""), 0)"),"https://nihcc.app.box.com/v/DeepLesion") -> https://nihcc.app.box.com/v/DeepLesion | J26: =IF(OR(F26="MRI", F26="Ultrasound", F26="Endoscopy", F26="Dermoscopy", F26="Fundus", F26="OCTA", F26="OCT"), F26, IF(OR(E26="Microscopy", E26="Histopathology", E26="Pathology", E26="CT", E26="PET", E26="X-Ray", E26="Mammography"), E26, "")) -> CT
